2025-05-08 11:49:39,659 DEBUG    root            Loaded Command Group: ['gcloud', 'projects']
2025-05-08 11:49:39,662 DEBUG    root            Loaded Command Group: ['gcloud', 'projects', 'describe']
2025-05-08 11:49:39,663 DEBUG    root            Running [gcloud.projects.describe] with arguments: [--account: "ian@clarahomecare.com", --configuration: "default", --format: "value(name)", PROJECT_ID_OR_NUMBER: "clara-production-430316"]
2025-05-08 11:49:39,676 DEBUG    google.auth.transport.requests Making request: POST https://oauth2.googleapis.com/token
2025-05-08 11:49:39,722 DEBUG    urllib3.connectionpool Starting new HTTPS connection (1): oauth2.googleapis.com:443
2025-05-08 11:49:39,867 DEBUG    urllib3.connectionpool https://oauth2.googleapis.com:443 "POST /token HTTP/11" 400 None
2025-05-08 11:49:39,868 DEBUG    root            (gcloud.projects.describe) There was a problem refreshing your current auth tokens: Reauthentication failed. cannot prompt during non-interactive execution.
Please run:

  $ gcloud auth login

to obtain new credentials.

If you have already logged in with a different account, run:

  $ gcloud config set account ACCOUNT

to select an already authenticated account to use.
Traceback (most recent call last):
  File "/Users/iangillis/google-cloud-sdk/lib/googlecloudsdk/core/credentials/google_auth_credentials.py", line 104, in refresh
    return self._Refresh(request)
  File "/Users/iangillis/google-cloud-sdk/lib/googlecloudsdk/core/credentials/google_auth_credentials.py", line 175, in _Refresh
    access_token, refresh_token, expiry, grant_response = _RefreshGrant(
  File "/Users/iangillis/google-cloud-sdk/lib/googlecloudsdk/core/credentials/google_auth_credentials.py", line 270, in _RefreshGrant
    response_data = _TokenEndpointRequestWithRetry(request, token_uri, body)
  File "/Users/iangillis/google-cloud-sdk/lib/googlecloudsdk/core/util/retry.py", line 307, in DecoratedFunction
    return retryer.RetryOnException(f, args=args, kwargs=kwargs,
  File "/Users/iangillis/google-cloud-sdk/lib/googlecloudsdk/core/util/retry.py", line 201, in RetryOnException
    exceptions.reraise(exc_info[1], tb=exc_info[2])
  File "/Users/iangillis/google-cloud-sdk/lib/googlecloudsdk/core/exceptions.py", line 149, in reraise
    six.reraise(type(exc_value), exc_value, tb)
  File "/Users/iangillis/google-cloud-sdk/lib/third_party/six/__init__.py", line 719, in reraise
    raise value
  File "/Users/iangillis/google-cloud-sdk/lib/googlecloudsdk/core/util/retry.py", line 182, in TryFunc
    return func(*args, **kwargs), None
  File "/Users/iangillis/google-cloud-sdk/lib/googlecloudsdk/core/credentials/google_auth_credentials.py", line 331, in _TokenEndpointRequestWithRetry
    _HandleErrorResponse(response_body)
  File "/Users/iangillis/google-cloud-sdk/lib/googlecloudsdk/core/credentials/google_auth_credentials.py", line 358, in _HandleErrorResponse
    raise ReauthRequiredError('reauth is required.')
googlecloudsdk.core.credentials.google_auth_credentials.ReauthRequiredError: reauth is required.

During handling of the above exception, another exception occurred:

Traceback (most recent call last):
  File "/Users/iangillis/google-cloud-sdk/lib/googlecloudsdk/core/credentials/store.py", line 1204, in HandleGoogleAuthCredentialsRefreshError
    yield
  File "/Users/iangillis/google-cloud-sdk/lib/googlecloudsdk/core/credentials/store.py", line 1338, in _RefreshGoogleAuth
    credentials.refresh(request_client)
  File "/Users/iangillis/google-cloud-sdk/lib/googlecloudsdk/core/credentials/creds.py", line 962, in _WrappedRefresh
    orig_refresh(request)
  File "/Users/iangillis/google-cloud-sdk/lib/googlecloudsdk/core/credentials/google_auth_credentials.py", line 107, in refresh
    raise google_auth_exceptions.ReauthFailError(
google.auth.exceptions.ReauthFailError: Reauthentication failed. cannot prompt during non-interactive execution.

During handling of the above exception, another exception occurred:

Traceback (most recent call last):
  File "/Users/iangillis/google-cloud-sdk/lib/googlecloudsdk/calliope/cli.py", line 981, in Execute
    resources = calliope_command.Run(cli=self, args=args)
  File "/Users/iangillis/google-cloud-sdk/lib/googlecloudsdk/calliope/backend.py", line 934, in Run
    resources = command_instance.Run(args)
  File "/Users/iangillis/google-cloud-sdk/lib/surface/projects/describe.py", line 51, in Run
    return projects_api.Get(project_ref)
  File "/Users/iangillis/google-cloud-sdk/lib/googlecloudsdk/api_lib/cloudresourcemanager/projects_api.py", line 124, in Get
    client = projects_util.GetClient(api_version)
  File "/Users/iangillis/google-cloud-sdk/lib/googlecloudsdk/api_lib/cloudresourcemanager/projects_util.py", line 56, in GetClient
    return apis.GetClientInstance(_API_NAME, version)
  File "/Users/iangillis/google-cloud-sdk/lib/googlecloudsdk/api_lib/util/apis.py", line 270, in GetClientInstance
    return apis_internal._GetClientInstance(
  File "/Users/iangillis/google-cloud-sdk/lib/googlecloudsdk/api_lib/util/apis_internal.py", line 169, in _GetClientInstance
    http_client = transports.GetApitoolsTransport(
  File "/Users/iangillis/google-cloud-sdk/lib/googlecloudsdk/core/credentials/transports.py", line 80, in GetApitoolsTransport
    session = requests.GetSession(
  File "/Users/iangillis/google-cloud-sdk/lib/googlecloudsdk/core/credentials/requests.py", line 82, in GetSession
    session = request_wrapper.WrapQuota(session, enable_resource_quota,
  File "/Users/iangillis/google-cloud-sdk/lib/googlecloudsdk/core/credentials/requests.py", line 127, in WrapQuota
    quota_project = self.QuotaProject(enable_resource_quota,
  File "/Users/iangillis/google-cloud-sdk/lib/googlecloudsdk/core/credentials/transport.py", line 54, in QuotaProject
    creds = store.LoadIfEnabled(allow_account_impersonation, use_google_auth)
  File "/Users/iangillis/google-cloud-sdk/lib/googlecloudsdk/core/credentials/store.py", line 636, in LoadIfEnabled
    return Load(
  File "/Users/iangillis/google-cloud-sdk/lib/googlecloudsdk/core/credentials/store.py", line 876, in Load
    cred = _Load(
  File "/Users/iangillis/google-cloud-sdk/lib/googlecloudsdk/core/credentials/store.py", line 1093, in _Load
    RefreshIfAlmostExpire(cred)
  File "/Users/iangillis/google-cloud-sdk/lib/googlecloudsdk/core/credentials/store.py", line 1451, in RefreshIfAlmostExpire
    RefreshIfExpireWithinWindow(credentials, window=_CREDENTIALS_EXPIRY_WINDOW)
  File "/Users/iangillis/google-cloud-sdk/lib/googlecloudsdk/core/credentials/store.py", line 1447, in RefreshIfExpireWithinWindow
    Refresh(credentials)
  File "/Users/iangillis/google-cloud-sdk/lib/googlecloudsdk/core/credentials/store.py", line 1133, in Refresh
    _RefreshGoogleAuth(credentials, is_impersonated_credential,
  File "/Users/iangillis/google-cloud-sdk/lib/googlecloudsdk/core/credentials/store.py", line 1338, in _RefreshGoogleAuth
    credentials.refresh(request_client)
  File "/Applications/Xcode.app/Contents/Developer/Library/Frameworks/Python3.framework/Versions/3.9/lib/python3.9/contextlib.py", line 135, in __exit__
    self.gen.throw(type, value, traceback)
  File "/Users/iangillis/google-cloud-sdk/lib/googlecloudsdk/core/credentials/store.py", line 1212, in HandleGoogleAuthCredentialsRefreshError
    raise creds_exceptions.TokenRefreshError(
googlecloudsdk.core.credentials.exceptions.TokenRefreshError: There was a problem refreshing your current auth tokens: Reauthentication failed. cannot prompt during non-interactive execution.
Please run:

  $ gcloud auth login

to obtain new credentials.

If you have already logged in with a different account, run:

  $ gcloud config set account ACCOUNT

to select an already authenticated account to use.
2025-05-08 11:49:39,898 ERROR    root            (gcloud.projects.describe) There was a problem refreshing your current auth tokens: Reauthentication failed. cannot prompt during non-interactive execution.
Please run:

  $ gcloud auth login

to obtain new credentials.

If you have already logged in with a different account, run:

  $ gcloud config set account ACCOUNT

to select an already authenticated account to use.
